08:33:28 PM: ERROR [cursor_del_pool.py:18] Ocurrió una excepción, se hace rollback: [WinError 233] No hay ningún proceso en el otro extremo de la canalización <class 'OSError'> <traceback object at 0x00000233570BCFC0>
08:34:12 PM: ERROR [cursor_del_pool.py:18] Ocurrió una excepción, se hace rollback: [WinError 233] No hay ningún proceso en el otro extremo de la canalización <class 'OSError'> <traceback object at 0x0000022557EE1800>
08:34:26 PM: ERROR [cursor_del_pool.py:18] Ocurrió una excepción, se hace rollback: [WinError 233] No hay ningún proceso en el otro extremo de la canalización <class 'OSError'> <traceback object at 0x000002333942CFC0>
08:34:51 PM: ERROR [cursor_del_pool.py:18] Ocurrió una excepción, se hace rollback: [WinError 233] No hay ningún proceso en el otro extremo de la canalización <class 'OSError'> <traceback object at 0x000001AF16658800>
08:35:18 PM: ERROR [cursor_del_pool.py:18] Ocurrió una excepción, se hace rollback: [WinError 233] No hay ningún proceso en el otro extremo de la canalización <class 'OSError'> <traceback object at 0x000001D3206897C0>
08:35:39 PM: ERROR [cursor_del_pool.py:18] Ocurrió una excepción, se hace rollback: [WinError 233] No hay ningún proceso en el otro extremo de la canalización <class 'OSError'> <traceback object at 0x0000022E7CD1CFC0>
08:36:09 PM: ERROR [cursor_del_pool.py:18] Ocurrió una excepción, se hace rollback: [WinError 233] No hay ningún proceso en el otro extremo de la canalización <class 'OSError'> <traceback object at 0x00000207A98F8800>
08:36:28 PM: ERROR [cursor_del_pool.py:18] Ocurrió una excepción, se hace rollback: [WinError 233] No hay ningún proceso en el otro extremo de la canalización <class 'OSError'> <traceback object at 0x0000016972778800>
08:36:40 PM: ERROR [cursor_del_pool.py:18] Ocurrió una excepción, se hace rollback: [WinError 233] No hay ningún proceso en el otro extremo de la canalización <class 'OSError'> <traceback object at 0x00000170B2288800>
08:37:04 PM: ERROR [cursor_del_pool.py:18] Ocurrió una excepción, se hace rollback: [WinError 233] No hay ningún proceso en el otro extremo de la canalización <class 'OSError'> <traceback object at 0x00000152631897C0>
08:38:00 PM: ERROR [cursor_del_pool.py:18] Ocurrió una excepción, se hace rollback: [WinError 233] No hay ningún proceso en el otro extremo de la canalización <class 'OSError'> <traceback object at 0x00000165E335CFC0>
08:38:25 PM: ERROR [cursor_del_pool.py:18] Ocurrió una excepción, se hace rollback: [WinError 233] No hay ningún proceso en el otro extremo de la canalización <class 'OSError'> <traceback object at 0x000001959B0F1800>
08:38:41 PM: ERROR [cursor_del_pool.py:18] Ocurrió una excepción, se hace rollback: [WinError 233] No hay ningún proceso en el otro extremo de la canalización <class 'OSError'> <traceback object at 0x00000227D6C18800>
08:39:12 PM: ERROR [cursor_del_pool.py:18] Ocurrió una excepción, se hace rollback: [WinError 233] No hay ningún proceso en el otro extremo de la canalización <class 'OSError'> <traceback object at 0x000002772F128800>
08:39:35 PM: ERROR [cursor_del_pool.py:18] Ocurrió una excepción, se hace rollback: [WinError 233] No hay ningún proceso en el otro extremo de la canalización <class 'OSError'> <traceback object at 0x00000275277A8800>
08:39:56 PM: ERROR [cursor_del_pool.py:18] Ocurrió una excepción, se hace rollback: [WinError 233] No hay ningún proceso en el otro extremo de la canalización <class 'OSError'> <traceback object at 0x000001A952A6CFC0>
08:40:15 PM: ERROR [cursor_del_pool.py:18] Ocurrió una excepción, se hace rollback: [WinError 233] No hay ningún proceso en el otro extremo de la canalización <class 'OSError'> <traceback object at 0x0000016EC2B2CFC0>
08:40:38 PM: ERROR [cursor_del_pool.py:18] Ocurrió una excepción, se hace rollback: [WinError 233] No hay ningún proceso en el otro extremo de la canalización <class 'OSError'> <traceback object at 0x00000189CA568800>
